2024-03-10 14:45:53,827 ERROR: Exception on /gridTimeseries [POST] [in /root/apis/wetterklima/venv/lib/python3.8/site-packages/flask/app.py:828]
Traceback (most recent call last):
  File "/root/apis/wetterklima/venv/lib/python3.8/site-packages/flask/app.py", line 1463, in wsgi_app
    response = self.full_dispatch_request()
  File "/root/apis/wetterklima/venv/lib/python3.8/site-packages/flask/app.py", line 872, in full_dispatch_request
    rv = self.handle_user_exception(e)
  File "/root/apis/wetterklima/venv/lib/python3.8/site-packages/flask/app.py", line 870, in full_dispatch_request
    rv = self.dispatch_request()
  File "/root/apis/wetterklima/venv/lib/python3.8/site-packages/flask/app.py", line 855, in dispatch_request
    return self.ensure_sync(self.view_functions[rule.endpoint])(**view_args)  # type: ignore[no-any-return]
  File "/root/apis/wetterklima/api/routes.py", line 94, in getGridTimeseries
    layerDate = request_data['layerDate']
KeyError: 'layerDate'
2024-03-10 14:45:53,831 ERROR: 500 Internal Server Error: The server encountered an internal error and was unable to complete your request. Either the server is overloaded or there is an error in the application. [in /root/apis/wetterklima/api/routes.py:32]
2024-03-10 14:46:49,506 ERROR: Exception on /gridTimeseries [POST] [in /root/apis/wetterklima/venv/lib/python3.8/site-packages/flask/app.py:828]
Traceback (most recent call last):
  File "/root/apis/wetterklima/venv/lib/python3.8/site-packages/flask/app.py", line 1463, in wsgi_app
    response = self.full_dispatch_request()
  File "/root/apis/wetterklima/venv/lib/python3.8/site-packages/flask/app.py", line 872, in full_dispatch_request
    rv = self.handle_user_exception(e)
  File "/root/apis/wetterklima/venv/lib/python3.8/site-packages/flask/app.py", line 870, in full_dispatch_request
    rv = self.dispatch_request()
  File "/root/apis/wetterklima/venv/lib/python3.8/site-packages/flask/app.py", line 855, in dispatch_request
    return self.ensure_sync(self.view_functions[rule.endpoint])(**view_args)  # type: ignore[no-any-return]
  File "/root/apis/wetterklima/api/routes.py", line 94, in getGridTimeseries
    layerDate = request_data['layerDate']
KeyError: 'layerDate'
2024-03-10 14:46:49,507 ERROR: 500 Internal Server Error: The server encountered an internal error and was unable to complete your request. Either the server is overloaded or there is an error in the application. [in /root/apis/wetterklima/api/routes.py:32]
2024-03-10 18:37:09,769 ERROR: Exception on /gridTimeseries [POST] [in /root/apis/wetterklima/venv/lib/python3.8/site-packages/flask/app.py:828]
Traceback (most recent call last):
  File "/root/apis/wetterklima/venv/lib/python3.8/site-packages/flask/app.py", line 1463, in wsgi_app
    response = self.full_dispatch_request()
  File "/root/apis/wetterklima/venv/lib/python3.8/site-packages/flask/app.py", line 872, in full_dispatch_request
    rv = self.handle_user_exception(e)
  File "/root/apis/wetterklima/venv/lib/python3.8/site-packages/flask/app.py", line 870, in full_dispatch_request
    rv = self.dispatch_request()
  File "/root/apis/wetterklima/venv/lib/python3.8/site-packages/flask/app.py", line 855, in dispatch_request
    return self.ensure_sync(self.view_functions[rule.endpoint])(**view_args)  # type: ignore[no-any-return]
  File "/root/apis/wetterklima/api/routes.py", line 94, in getGridTimeseries
    layerDate = request_data['layerDate']
KeyError: 'layerDate'
2024-03-10 18:37:09,771 ERROR: 500 Internal Server Error: The server encountered an internal error and was unable to complete your request. Either the server is overloaded or there is an error in the application. [in /root/apis/wetterklima/api/routes.py:32]
2024-03-10 19:10:39,959 ERROR: Exception on /gridTimeseries [POST] [in /root/apis/wetterklima/venv/lib/python3.8/site-packages/flask/app.py:828]
Traceback (most recent call last):
  File "/root/apis/wetterklima/venv/lib/python3.8/site-packages/flask/app.py", line 1463, in wsgi_app
    response = self.full_dispatch_request()
  File "/root/apis/wetterklima/venv/lib/python3.8/site-packages/flask/app.py", line 872, in full_dispatch_request
    rv = self.handle_user_exception(e)
  File "/root/apis/wetterklima/venv/lib/python3.8/site-packages/flask/app.py", line 870, in full_dispatch_request
    rv = self.dispatch_request()
  File "/root/apis/wetterklima/venv/lib/python3.8/site-packages/flask/app.py", line 855, in dispatch_request
    return self.ensure_sync(self.view_functions[rule.endpoint])(**view_args)  # type: ignore[no-any-return]
  File "/root/apis/wetterklima/api/routes.py", line 94, in getGridTimeseries
    layerDate = request_data['layerDate']
KeyError: 'layerDate'
2024-03-10 19:10:39,959 ERROR: 500 Internal Server Error: The server encountered an internal error and was unable to complete your request. Either the server is overloaded or there is an error in the application. [in /root/apis/wetterklima/api/routes.py:32]
2024-03-10 19:10:42,537 ERROR: Exception on /gridTimeseries [POST] [in /root/apis/wetterklima/venv/lib/python3.8/site-packages/flask/app.py:828]
Traceback (most recent call last):
  File "/root/apis/wetterklima/venv/lib/python3.8/site-packages/flask/app.py", line 1463, in wsgi_app
    response = self.full_dispatch_request()
  File "/root/apis/wetterklima/venv/lib/python3.8/site-packages/flask/app.py", line 872, in full_dispatch_request
    rv = self.handle_user_exception(e)
  File "/root/apis/wetterklima/venv/lib/python3.8/site-packages/flask/app.py", line 870, in full_dispatch_request
    rv = self.dispatch_request()
  File "/root/apis/wetterklima/venv/lib/python3.8/site-packages/flask/app.py", line 855, in dispatch_request
    return self.ensure_sync(self.view_functions[rule.endpoint])(**view_args)  # type: ignore[no-any-return]
  File "/root/apis/wetterklima/api/routes.py", line 94, in getGridTimeseries
    layerDate = request_data['layerDate']
KeyError: 'layerDate'
2024-03-10 19:10:42,538 ERROR: 500 Internal Server Error: The server encountered an internal error and was unable to complete your request. Either the server is overloaded or there is an error in the application. [in /root/apis/wetterklima/api/routes.py:32]
2024-03-10 19:10:46,523 ERROR: Exception on /gridTimeseries [POST] [in /root/apis/wetterklima/venv/lib/python3.8/site-packages/flask/app.py:828]
Traceback (most recent call last):
  File "/root/apis/wetterklima/venv/lib/python3.8/site-packages/flask/app.py", line 1463, in wsgi_app
    response = self.full_dispatch_request()
  File "/root/apis/wetterklima/venv/lib/python3.8/site-packages/flask/app.py", line 872, in full_dispatch_request
    rv = self.handle_user_exception(e)
  File "/root/apis/wetterklima/venv/lib/python3.8/site-packages/flask/app.py", line 870, in full_dispatch_request
    rv = self.dispatch_request()
  File "/root/apis/wetterklima/venv/lib/python3.8/site-packages/flask/app.py", line 855, in dispatch_request
    return self.ensure_sync(self.view_functions[rule.endpoint])(**view_args)  # type: ignore[no-any-return]
  File "/root/apis/wetterklima/api/routes.py", line 94, in getGridTimeseries
    layerDate = request_data['layerDate']
KeyError: 'layerDate'
2024-03-10 19:10:46,523 ERROR: 500 Internal Server Error: The server encountered an internal error and was unable to complete your request. Either the server is overloaded or there is an error in the application. [in /root/apis/wetterklima/api/routes.py:32]
2024-03-10 19:15:42,706 ERROR: Exception on /gridTimeseries [POST] [in /root/apis/wetterklima/venv/lib/python3.8/site-packages/flask/app.py:828]
Traceback (most recent call last):
  File "/root/apis/wetterklima/venv/lib/python3.8/site-packages/flask/app.py", line 1463, in wsgi_app
    response = self.full_dispatch_request()
  File "/root/apis/wetterklima/venv/lib/python3.8/site-packages/flask/app.py", line 872, in full_dispatch_request
    rv = self.handle_user_exception(e)
  File "/root/apis/wetterklima/venv/lib/python3.8/site-packages/flask/app.py", line 870, in full_dispatch_request
    rv = self.dispatch_request()
  File "/root/apis/wetterklima/venv/lib/python3.8/site-packages/flask/app.py", line 855, in dispatch_request
    return self.ensure_sync(self.view_functions[rule.endpoint])(**view_args)  # type: ignore[no-any-return]
  File "/root/apis/wetterklima/api/routes.py", line 121, in getGridTimeseries
    timeseries_with_stats = utils.create_timeseries_object(timeseries)
  File "/root/apis/wetterklima/utils.py", line 292, in create_timeseries_object
    timeseries_stats = calculate_stats_for_timeseries(timeseries)
  File "/root/apis/wetterklima/utils.py", line 236, in calculate_stats_for_timeseries
    overall_min = df.loc[df['value'].idxmin()].values.tolist()
  File "/root/apis/wetterklima/venv/lib/python3.8/site-packages/pandas/core/series.py", line 2460, in idxmin
    i = self.argmin(axis, skipna, *args, **kwargs)  # type: ignore[arg-type]
  File "/root/apis/wetterklima/venv/lib/python3.8/site-packages/pandas/core/base.py", line 742, in argmin
    return nanops.nanargmin(  # type: ignore[return-value]
  File "/root/apis/wetterklima/venv/lib/python3.8/site-packages/pandas/core/nanops.py", line 91, in _f
    raise TypeError(
TypeError: reduction operation 'argmin' not allowed for this dtype
2024-03-10 19:15:42,714 ERROR: 500 Internal Server Error: The server encountered an internal error and was unable to complete your request. Either the server is overloaded or there is an error in the application. [in /root/apis/wetterklima/api/routes.py:32]
